Workbook

Sheet Score Entry
A1: EvalAI — Hypothesis Testing Score Collection Sheet
A2: Fill in the AI scores from EvalAI for each answer. Yellow cells = enter your scores.
A4: # | B4: Question | C4: Scenario | D4: Expected Score | E4: AI Score (Fill Here) | F4: Difference | G4: Within Range? | H4: Similarity % | I4: Entailment %
A5: Q1 | B5: Why are String objects immutable in Java? Discuss with at least one advantage. | C5: Fully Correct | D5: 9.5 | E5: 8.05 | F5: =IF(E5="","",E5-D5) -> -1.45 | G5: =IF(E5="","",IF(AND(E5>=9,E5<=10),"✓ Yes","✗ No")) -> ✗ No | H5: 0.9 | I5: 1
C6: Above Average | D6: 7.5 | E6: 7.1 | F6: =IF(E6="","",E6-D6) -> -0.4 | G6: =IF(E6="","",IF(AND(E6>=7,E6<=9),"✓ Yes","✗ No")) -> ✓ Yes | H6: 0.78 | I6: 1
C7: Average | D7: 5.5 | E7: 5.33 | F7: =IF(E7="","",E7-D7) -> -0.17 | G7: =IF(E7="","",IF(AND(E7>=4.5,E7<=7),"✓ Yes","✗ No")) -> ✓ Yes | H7: 0.68 | I7: 0.96
C8: Below Average | D8: 3.5 | E8: 4.31 | F8: =IF(E8="","",E8-D8) -> 0.81 | G8: =IF(E8="","",IF(AND(E8>=2.5,E8<=4.5),"✓ Yes","✗ No")) -> ✓ Yes | H8: 0.47 | I8: 0.99
C9: Fully Wrong | D9: 1.5 | E9: 3.22 | F9: =IF(E9="","",E9-D9) -> 1.72 | G9: =IF(E9="","",IF(AND(E9>=0,E9<=2.5),"✓ Yes","✗ No")) -> ✗ No | H9: 0.76 | I9: 0
A11: Q2 | B11: Discuss the difference between HashMap and ConcurrentHashMap in Java. | C11: Fully Correct | D11: 9.5 | E11: 7.52 | F11: =IF(E11="","",E11-D11) -> -1.98 | G11: =IF(E11="","",IF(AND(E11>=9,E11<=10),"✓ Yes","✗ No")) -> ✗ No | H11: 0.94 | I11: 1
C12: Above Average | D12: 7.5 | E12: 5.99 | F12: =IF(E12="","",E12-D12) -> -1.51 | G12: =IF(E12="","",IF(AND(E12>=7,E12<=9),"✓ Yes","✗ No")) -> ✗ No | H12: 0.95 | I12: 0.97
C13: Average | D13: 5.5 | E13: 7.02 | F13: =IF(E13="","",E13-D13) -> 1.52 | G13: =IF(E13="","",IF(AND(E13>=4.5,E13<=7),"✓ Yes","✗ No")) -> ✗ No | H13: 0.93 | I13: 0.98
C14: Below Average | D14: 3.5 | E14: 3.67 | F14: =IF(E14="","",E14-D14) -> 0.17 | G14: =IF(E14="","",IF(AND(E14>=2.5,E14<=4.5),"✓ Yes","✗ No")) -> ✓ Yes | H14: 0.83 | I14: 0.01
C15: Fully Wrong | D15: 1.5 | E15: 3.66 | F15: =IF(E15="","",E15-D15) -> 2.16 | G15: =IF(E15="","",IF(AND(E15>=0,E15<=2.5),"✓ Yes","✗ No")) -> ✗ No | H15: 0.9 | I15: 0
A17: Q3 | B17: What is Java? | C17: Fully Correct | D17: 9.5 | E17: 9.52 | F17: =IF(E17="","",E17-D17) -> 0.02 | G17: =IF(E17="","",IF(AND(E17>=9,E17<=10),"✓ Yes","✗ No")) -> ✓ Yes | H17: 0.99 | I17: 0.99
C18: Above Average | D18: 7.5 | E18: 6.81 | F18: =IF(E18="","",E18-D18) -> -0.69 | G18: =IF(E18="","",IF(AND(E18>=7,E18<=9),"✓ Yes","✗ No")) -> ✗ No | H18: 0.9 | I18: 0.99
C19: Average | D19: 5.5 | E19: 5.4 | F19: =IF(E19="","",E19-D19) -> -0.1 | G19: =IF(E19="","",IF(AND(E19>=4.5,E19<=7),"✓ Yes","✗ No")) -> ✓ Yes | H19: 0.71 | I19: 0.75
C20: Below Average | D20: 3.5 | E20: 3.05 | F20: =IF(E20="","",E20-D20) -> -0.45 | G20: =IF(E20="","",IF(AND(E20>=2.5,E20<=4.5),"✓ Yes","✗ No")) -> ✓ Yes | H20: 0.64 | I20: 0.02
C21: Fully Wrong | D21: 1.5 | E21: 3.12 | F21: =IF(E21="","",E21-D21) -> 1.62 | G21: =IF(E21="","",IF(AND(E21>=0,E21<=2.5),"✓ Yes","✗ No")) -> ✗ No | H21: 0.68 | I21: 0
A23: Q4 | B23: What is OOP in Java? | C23: Fully Correct | D23: 9.5 | E23: 8.08 | F23: =IF(E23="","",E23-D23) -> -1.42 | G23: =IF(E23="","",IF(AND(E23>=9,E23<=10),"✓ Yes","✗ No")) -> ✗ No | H23: 0.99 | I23: 1
C24: Above Average | D24: 7.5 | E24: 6.97 | F24: =IF(E24="","",E24-D24) -> -0.53 | G24: =IF(E24="","",IF(AND(E24>=7,E24<=9),"✓ Yes","✗ No")) -> ✗ No | H24: 0.93 | I24: 1
C25: Average | D25: 5.5 | E25: 6.58 | F25: =IF(E25="","",E25-D25) -> 1.08 | G25: =IF(E25="","",IF(AND(E25>=4.5,E25<=7),"✓ Yes","✗ No")) -> ✓ Yes | H25: 0.92 | I25: 1
C26: Below Average | D26: 3.5 | E26: 3.66 | F26: =IF(E26="","",E26-D26) -> 0.16 | G26: =IF(E26="","",IF(AND(E26>=2.5,E26<=4.5),"✓ Yes","✗ No")) -> ✓ Yes | H26: 0.78 | I26: 0
C27: Fully Wrong | D27: 1.5 | E27: 3.39 | F27: =IF(E27="","",E27-D27) -> 1.89 | G27: =IF(E27="","",IF(AND(E27>=0,E27<=2.5),"✓ Yes","✗ No")) -> ✗ No | H27: 0.74 | I27: 0
A29: Q5 | B29: What is a Class and Object? | C29: Fully Correct | D29: 9.5 | E29: 9.05 | F29: =IF(E29="","",E29-D29) -> -0.45 | G29: =IF(E29="","",IF(AND(E29>=9,E29<=10),"✓ Yes","✗ No")) -> ✓ Yes | H29: 0.96 | I29: 0.99
C30: Above Average | D30: 7.5 | E30: 7.9 | F30: =IF(E30="","",E30-D30) -> 0.4 | G30: =IF(E30="","",IF(AND(E30>=7,E30<=9),"✓ Yes","✗ No")) -> ✓ Yes | H30: 0.73 | I30: 1
C31: Average | D31: 5.5 | E31: 4.68 | F31: =IF(E31="","",E31-D31) -> -0.82 | G31: =IF(E31="","",IF(AND(E31>=4.5,E31<=7),"✓ Yes","✗ No")) -> ✓ Yes | H31: 0.67 | I31: 0
C32: Below Average | D32: 3.5 | E32: 6.18 | F32: =IF(E32="","",E32-D32) -> 2.68 | G32: =IF(E32="","",IF(AND(E32>=2.5,E32<=4.5),"✓ Yes","✗ No")) -> ✗ No | H32: 0.74 | I32: 0.99
C33: Fully Wrong | D33: 1.5 | E33: 4.12 | F33: =IF(E33="","",E33-D33) -> 2.62 | G33: =IF(E33="","",IF(AND(E33>=0,E33<=2.5),"✓ Yes","✗ No")) -> ✗ No | H33: 0.67 | I33: 0
A35: Q6 | B35: What is Inheritance? | C35: Fully Correct | D35: 9.5 | E35: 8.11 | F35: =IF(E35="","",E35-D35) -> -1.39 | G35: =IF(E35="","",IF(AND(E35>=9,E35<=10),"✓ Yes","✗ No")) -> ✗ No | H35: 0.92 | I35: 0.99
C36: Above Average | D36: 7.5 | E36: 5.92 | F36: =IF(E36="","",E36-D36) -> -1.58 | G36: =IF(E36="","",IF(AND(E36>=7,E36<=9),"✓ Yes","✗ No")) -> ✗ No | H36: 0.71 | I36: 0.99
C37: Average | D37: 5.5 | E37: 5.19 | F37: =IF(E37="","",E37-D37) -> -0.31 | G37: =IF(E37="","",IF(AND(E37>=4.5,E37<=7),"✓ Yes","✗ No")) -> ✓ Yes | H37: 0.74 | I37: 0.81
C38: Below Average | D38: 3.5 | E38: 2.52 | F38: =IF(E38="","",E38-D38) -> -0.98 | G38: =IF(E38="","",IF(AND(E38>=2.5,E38<=4.5),"✓ Yes","✗ No")) -> ✓ Yes | H38: 0.55 | I38: 0.01
C39: Fully Wrong | D39: 1.5 | E39: 3.11 | F39: =IF(E39="","",E39-D39) -> 1.61 | G39: =IF(E39="","",IF(AND(E39>=0,E39<=2.5),"✓ Yes","✗ No")) -> ✗ No | H39: 0.66 | I39: 0
A41: Q7 | B41: What is JVM? | C41: Fully Correct | D41: 9.5 | E41: 9.93 | F41: =IF(E41="","",E41-D41) -> 0.43 | G41: =IF(E41="","",IF(AND(E41>=9,E41<=10),"✓ Yes","✗ No")) -> ✓ Yes | H41: 0.99 | I41: 1
C42: Above Average | D42: 7.5 | E42: 7.72 | F42: =IF(E42="","",E42-D42) -> 0.22 | G42: =IF(E42="","",IF(AND(E42>=7,E42<=9),"✓ Yes","✗ No")) -> ✓ Yes | H42: 0.86 | I42: 1
C43: Average | D43: 5.5 | E43: 6.21 | F43: =IF(E43="","",E43-D43) -> 0.71 | G43: =IF(E43="","",IF(AND(E43>=4.5,E43<=7),"✓ Yes","✗ No")) -> ✓ Yes | H43: 0.85 | I43: 1
C44: Below Average | D44: 3.5 | E44: 5.84 | F44: =IF(E44="","",E44-D44) -> 2.34 | G44: =IF(E44="","",IF(AND(E44>=2.5,E44<=4.5),"✓ Yes","✗ No")) -> ✗ No | H44: 0.78 | I44: 0.98
C45: Fully Wrong | D45: 1.5 | E45: 4.2 | F45: =IF(E45="","",E45-D45) -> 2.7 | G45: =IF(E45="","",IF(AND(E45>=0,E45<=2.5),"✓ Yes","✗ No")) -> ✗ No | H45: 0.79 | I45: 0.21
A47: Q8 | B47: What is a variable in Java? | C47: Fully Correct | D47: 9.5 | E47: 9.77 | F47: =IF(E47="","",E47-D47) -> 0.27 | G47: =IF(E47="","",IF(AND(E47>=9,E47<=10),"✓ Yes","✗ No")) -> ✓ Yes | H47: 0.98 | I47: 0.94
C48: Above Average | D48: 7.5 | E48: 7.14 | F48: =IF(E48="","",E48-D48) -> -0.36 | G48: =IF(E48="","",IF(AND(E48>=7,E48<=9),"✓ Yes","✗ No")) -> ✓ Yes | H48: 0.81 | I48: 0.96
...

Sheet Statistics Summary
A1: EvalAI — Statistical Summary (Auto-Calculated)
A2: Scores auto-pull from Score Entry sheet. Fill Column E there first.
A4: Group Statistics per Scenario
A5: Scenario | B5: Expected Midpoint | C5: Mean AI Score | D5: Std Dev | E5: Min | F5: Max | G5: Within Range %
A6: Fully Correct | B6: 9.5 | C6: =IFERROR(AVERAGE('Score Entry'!E5,'Score Entry'!E11,'Score Entry'!E17,'Score Entry'!E23,'Score Entry'!E29,'Score Entry'!E35,'Score Entry'!E41,'Score Entry'!E47,'Score Entry'!E53,'Score Entry'!E59),"Fill scores") -> 8.978 | D6: =IFERROR(STDEV('Score Entry'!E5,'Score Entry'!E11,'Score Entry'!E17,'Score Entry'!E23,'Score Entry'!E29,'Score Entry'!E35,'Score Entry'!E41,'Score Entry'!E47,'Score Entry'!E53,'Score Entry'!E59),"") -> 0.94298345 | E6: =IFERROR(MIN('Score Entry'!E5,'Score Entry'!E11,'Score Entry'!E17,'Score Entry'!E23,'Score Entry'!E29,'Score Entry'!E35,'Score Entry'!E41,'Score Entry'!E47,'Score Entry'!E53,'Score Entry'!E59),"") -> 7.52 | F6: =IFERROR(MAX('Score Entry'!E5,'Score Entry'!E11,'Score Entry'!E17,'Score Entry'!E23,'Score Entry'!E29,'Score Entry'!E35,'Score Entry'!E41,'Score Entry'!E47,'Score Entry'!E53,'Score Entry'!E59),"") -> 9.96
A7: Above Average | B7: 7.5 | C7: =IFERROR(AVERAGE('Score Entry'!E6,'Score Entry'!E12,'Score Entry'!E18,'Score Entry'!E24,'Score Entry'!E30,'Score Entry'!E36,'Score Entry'!E42,'Score Entry'!E48,'Score Entry'!E54,'Score Entry'!E60),"Fill scores") -> 7.158 | D7: =IFERROR(STDEV('Score Entry'!E6,'Score Entry'!E12,'Score Entry'!E18,'Score Entry'!E24,'Score Entry'!E30,'Score Entry'!E36,'Score Entry'!E42,'Score Entry'!E48,'Score Entry'!E54,'Score Entry'!E60),"") -> 1.0725649 | E7: =IFERROR(MIN('Score Entry'!E6,'Score Entry'!E12,'Score Entry'!E18,'Score Entry'!E24,'Score Entry'!E30,'Score Entry'!E36,'Score Entry'!E42,'Score Entry'!E48,'Score Entry'!E54,'Score Entry'!E60),"") -> 5.92 | F7: =IFERROR(MAX('Score Entry'!E6,'Score Entry'!E12,'Score Entry'!E18,'Score Entry'!E24,'Score Entry'!E30,'Score Entry'!E36,'Score Entry'!E42,'Score Entry'!E48,'Score Entry'!E54,'Score Entry'!E60),"") -> 9.59
A8: Average | B8: 5.5 | C8: =IFERROR(AVERAGE('Score Entry'!E7,'Score Entry'!E13,'Score Entry'!E19,'Score Entry'!E25,'Score Entry'!E31,'Score Entry'!E37,'Score Entry'!E43,'Score Entry'!E49,'Score Entry'!E55,'Score Entry'!E61),"Fill scores") -> 5.936 | D8: =IFERROR(STDEV('Score Entry'!E7,'Score Entry'!E13,'Score Entry'!E19,'Score Entry'!E25,'Score Entry'!E31,'Score Entry'!E37,'Score Entry'!E43,'Score Entry'!E49,'Score Entry'!E55,'Score Entry'!E61),"") -> 0.86842386 | E8: =IFERROR(MIN('Score Entry'!E7,'Score Entry'!E13,'Score Entry'!E19,'Score Entry'!E25,'Score Entry'!E31,'Score Entry'!E37,'Score Entry'!E43,'Score Entry'!E49,'Score Entry'!E55,'Score Entry'!E61),"") -> 4.68 | F8: =IFERROR(MAX('Score Entry'!E7,'Score Entry'!E13,'Score Entry'!E19,'Score Entry'!E25,'Score Entry'!E31,'Score Entry'!E37,'Score Entry'!E43,'Score Entry'!E49,'Score Entry'!E55,'Score Entry'!E61),"") -> 7.18
A9: Below Average | B9: 3.5 | C9: =IFERROR(AVERAGE('Score Entry'!E8,'Score Entry'!E14,'Score Entry'!E20,'Score Entry'!E26,'Score Entry'!E32,'Score Entry'!E38,'Score Entry'!E44,'Score Entry'!E50,'Score Entry'!E56,'Score Entry'!E62),"Fill scores") -> 4.478 | D9: =IFERROR(STDEV('Score Entry'!E8,'Score Entry'!E14,'Score Entry'!E20,'Score Entry'!E26,'Score Entry'!E32,'Score Entry'!E38,'Score Entry'!E44,'Score Entry'!E50,'Score Entry'!E56,'Score Entry'!E62),"") -> 1.3846363 | E9: =IFERROR(MIN('Score Entry'!E8,'Score Entry'!E14,'Score Entry'!E20,'Score Entry'!E26,'Score Entry'!E32,'Score Entry'!E38,'Score Entry'!E44,'Score Entry'!E50,'Score Entry'!E56,'Score Entry'!E62),"") -> 2.52 | F9: =IFERROR(MAX('Score Entry'!E8,'Score Entry'!E14,'Score Entry'!E20,'Score Entry'!E26,'Score Entry'!E32,'Score Entry'!E38,'Score Entry'!E44,'Score Entry'!E50,'Score Entry'!E56,'Score Entry'!E62),"") -> 6.75
A10: Fully Wrong | B10: 1.5 | C10: =IFERROR(AVERAGE('Score Entry'!E9,'Score Entry'!E15,'Score Entry'!E21,'Score Entry'!E27,'Score Entry'!E33,'Score Entry'!E39,'Score Entry'!E45,'Score Entry'!E51,'Score Entry'!E57,'Score Entry'!E63),"Fill scores") -> 3.262 | D10: =IFERROR(STDEV('Score Entry'!E9,'Score Entry'!E15,'Score Entry'!E21,'Score Entry'!E27,'Score Entry'!E33,'Score Entry'!E39,'Score Entry'!E45,'Score Entry'!E51,'Score Entry'!E57,'Score Entry'!E63),"") -> 1.2125254 | E10: =IFERROR(MIN('Score Entry'!E9,'Score Entry'!E15,'Score Entry'!E21,'Score Entry'!E27,'Score Entry'!E33,'Score Entry'!E39,'Score Entry'!E45,'Score Entry'!E51,'Score Entry'!E57,'Score Entry'!E63),"") -> 0.02 | F10: =IFERROR(MAX('Score Entry'!E9,'Score Entry'!E15,'Score Entry'!E21,'Score Entry'!E27,'Score Entry'!E33,'Score Entry'!E39,'Score Entry'!E45,'Score Entry'!E51,'Score Entry'!E57,'Score Entry'!E63),"") -> 4.2
A13: Hypothesis Testing — ANOVA Results
A14: After filling all scores → run hypothesis_test.py to get F-statistic, p-value, and charts
A15: H0 (Null Hypothesis) | B15: All 5 scenario groups have the same mean score
A16: H1 (Alternative Hypothesis) | B16: At least one group mean is significantly different
A17: Statistical Test | B17: One-Way ANOVA with Tukey HSD Post-Hoc
A18: Significance Level (α) | B18: 0.05
A19: Sample Size | B19: n = 10 per group, 50 total answers
A20: Decision Rule | B20: If p-value < 0.05 → REJECT H0 → Model validated!

Sheet Instructions
A1: How to use this sheet — Step by Step
A3: Step 1 | B3: Run all 50 answers through EvalAI system (10 questions × 5 scenarios)
A4: Step 2 | B4: Go to 'Score Entry' sheet → fill in AI Score (column E) for each answer
A5: Step 3 | B5: Also fill Similarity % (col H) and Entailment % (col I) if you want extra analysis
A6: Step 4 | B6: Check 'Statistics Summary' sheet — means auto-calculate as you fill scores
A7: Step 5 | B7: Once all 50 scores filled → run: python hypothesis_test.py
A8: Step 6 | B8: Replace scores in hypothesis_test.py with your actual scores from column E
A9: Step 7 | B9: Run the script → get F-statistic, p-value, charts → show to sir!
A11: Yellow cells | B11: =AI Score input — MUST fill these (Column E in Score Entry) -> #NAME?
A12: Green cells
A13: Blue cells
A15: Expected range | B15: Fully Correct: 9.0–10.0 | Above Average: 7.0–9.0 | Average: 4.5–7.0
A16: Expected range | B16: Below Average: 2.5–4.5 | Fully Wrong: 0.0–2.5
